#VRML_SIM R2020b utf8
WorldInfo {
  info [
    "Example of \"laser\" DistanceSensors used together with a Camera."
  ]
  title "Laser Pointers"
  basicTimeStep 8
  coordinateSystem "NUE"
}
Viewpoint {
  orientation -0.8763596147774195 0.4351487063085177 0.2064931693427084 0.4622890990009302
  position 0.16203665219054816 0.5915099237848733 1.1758542409967891
}
TexturedBackground {
}
TexturedBackgroundLight {
}
RectangleArena {
}
Robot {
  translation -0.492426 0.05 -0.492426
  rotation 0 1 0 -0.785395307179586
  children [
    Shape {
      appearance Appearance {
        material Material {
          diffuseColor 0.8 0 0.8
        }
      }
      geometry Box {
        size 0.1 0.1 0.1
      }
    } 
    Emitter {
    }
  ]
  recognitionColors [
    0 1 0
  ]
  controller "emitter_ctrl"
}
DEF BLUE_BOX Solid {
  translation 0.179652514257284 0.017766445632009388 0.019789912818454974
  rotation -6.609137182397111e-16 -1 4.338746045464758e-16 1.7824476510729326
  scale 0.355417 0.355417 0.355417
  children [
    Shape {
      appearance PBRAppearance {
        baseColor 0 0 1
        roughness 0.519341125
        metalness 0
      }
      geometry DEF BOX1 Box {
        size 0.1 0.1 0.1
      }
    }
  ]
  name "blue box"
  boundingObject Shape {
    appearance PBRAppearance {
      roughness 1.1102230246251565e-16
      metalness 0
    }
    geometry USE BOX1
  }
  physics Physics {
  }
  recognitionColors [
    0 0 1
  ]
}
DEF ROBOT Robot {
  translation -0.0135328 -0.00280407 0.0785144
  rotation -0.015809200773669103 0.9996420489203838 -0.021583401056246346 2.31186
  children [
    Receiver {
    }
    Transform {
      translation 0 0.0615 0
      children [
        Shape {
          appearance PBRAppearance {
            baseColor 1 0.4 1
          }
          geometry Cylinder {
            height 0.1
            radius 0.04
          }
        }
        Solid {
          translation 0.035 -0.05 -0.06
          rotation 0.7546688555575023 0.6561058744223104 2.5500495119243123e-07 6.21834e-06
          children [
            DEF lapa1 Shape {
              appearance PBRAppearance {
              }
              geometry Box {
                size 0.01 0.01 0.09
              }
            }
          ]
          name "solid(2)"
          boundingObject USE lapa1
          physics Physics {
          }
        }
        Solid {
          translation 0 -0.05 0.02
          children [
            DEF zopa Shape {
              appearance PBRAppearance {
              }
              geometry Box {
                size 0.02 0.02 0.1
              }
            }
          ]
          name "solid(4)"
          boundingObject USE zopa
          physics Physics {
          }
        }
        Solid {
          translation -0.035 -0.05 -0.06
          rotation 0.7546688555575023 0.6561058744223104 2.5500495119243123e-07 6.21834e-06
          children [
            DEF lapa2 Shape {
              appearance PBRAppearance {
              }
              geometry Box {
                size 0.01 0.01 0.09
              }
            }
          ]
          name "solid(3)"
          boundingObject USE lapa2
          physics Physics {
          }
        }
        Shape {
          appearance PBRAppearance {
            baseColor 0.0820075 0.364728 0.8
            roughness 1
            metalness 0
          }
          geometry DEF BODY Cylinder {
            height 0.08
            radius 0.045
          }
        }
        Solid {
          translation 0 0.13 0.02
          children [
            Shape {
              appearance PBRAppearance {
                baseColor 1 0 1
              }
              geometry Box {
                size 0.001 0.03 0.05
              }
            }
          ]
          name "solid(1)"
        }
        Solid {
          translation 0 0.09 0
          children [
            Shape {
              appearance PBRAppearance {
                baseColor 1 0.2 1
              }
              geometry Cylinder {
                height 0.1
                radius 0.002
              }
            }
          ]
        }
      ]
    }
    HingeJoint {
      jointParameters HingeJointParameters {
        position -40.567995855940666
        axis -1 0 0
        anchor 0 0.025 0
      }
      device [
        RotationalMotor {
          name "left wheel motor"
          consumptionFactor 70
        }
        PositionSensor {
          name "left wheel sensor"
        }
      ]
      endPoint Solid {
        translation -0.04499999999999953 0.025 0
        rotation -1 0 0 4.712816601496025
        children [
          DEF WHEEL Transform {
            rotation 0 0 1 1.57
            children [
              Shape {
                appearance PBRAppearance {
                  baseColor 0.2 0 0
                  roughness 1
                  metalness 0
                }
                geometry Cylinder {
                  height 0.01
                  radius 0.025
                }
              }
            ]
          }
        ]
        name "left wheel"
        boundingObject USE WHEEL
        physics DEF PHYSICS_WHEEL Physics {
          density -1
          mass 0.05
        }
      }
    }
    HingeJoint {
      jointParameters HingeJointParameters {
        position 69.12799327053565
        axis -1 0 0
        anchor 0 0.025 0
      }
      device [
        RotationalMotor {
          name "right wheel motor"
          consumptionFactor 70
        }
        PositionSensor {
          name "right wheel sensor"
        }
      ]
      endPoint Solid {
        translation 0.04499999999999986 0.025 0
        rotation -1 0 0 1.70879019873979
        children [
          USE WHEEL
        ]
        name "right wheel"
        boundingObject USE WHEEL
        physics USE PHYSICS_WHEEL
      }
    }
    DEF SMILE Transform {
      translation 0 0.025 -0.036
      rotation 0.7745972408364944 0.44721228048294853 0.4472139204829502 1.8234794
      children [
        Shape {
          appearance PBRAppearance {
            baseColor 0.721569 0.290196 0.290196
            roughness 1
            metalness 0
          }
          geometry Cylinder {
            height 0.018
            radius 0.009
            subdivision 3
          }
        }
      ]
    }
    Camera {
      translation 0 0.0515 -0.05
      rotation 1 0 0 4.692820414042842e-06
      scale 0.406043 0.406043 0.406043
      children [
        Transform {
          translation 0 0 0.015
          rotation 1 0 0 1.57
          children [
            Shape {
              appearance PBRAppearance {
                roughness 1
                metalness 0
              }
              geometry Cylinder {
                height 0.03
                radius 0.01
              }
            }
          ]
        }
      ]
      fieldOfView 1.047
      width 80
      height 60
      near 0.001
      antiAliasing TRUE
      recognition Recognition {
      }
    }
  ]
  name "MyBot"
  boundingObject Transform {
    translation 0 0.0515 0
    children [
      USE BODY
    ]
  }
  physics Physics {
    density -1
    mass 0.5
  }
  controller "24crn"
  controllerArgs [
    "<'extern'>"
  ]
}
