#VRML_SIM R2020b utf8
WorldInfo {
  info [
    "The model of the E-puck robot"
  ]
  title "E-puck simulation"
  coordinateSystem "NUE"
}
Viewpoint {
  orientation 0.0027407764974660674 0.9998906684531774 0.014530632623843685 2.863960324689508
  position 0.2554274368165711 0.32380772736253666 -1.2584267260691375
}
TexturedBackground {
}
TexturedBackgroundLight {
}
Solid {
  translation -0.68 0.1 -0.56
  children [
    DEF shar1 Shape {
      appearance PBRAppearance {
        baseColor 1 1 0
        metalness 0
      }
      geometry Sphere {
        radius 0.03
      }
    }
  ]
  boundingObject USE shar1
  physics Physics {
  }
  recognitionColors [
    1 1 0
  ]
}
Solid {
  translation -0.68 0.1 0.64
  children [
    DEF shar2 Shape {
      appearance PBRAppearance {
        baseColor 1 1 0
        metalness 0
      }
      geometry Sphere {
        radius 0.03
      }
    }
  ]
  name "solid(1)"
  boundingObject USE shar2
  physics Physics {
  }
  recognitionColors [
    1 1 0
  ]
}
Solid {
  translation 0.6 0.1 -0.56
  children [
    DEF shar3 Shape {
      appearance PBRAppearance {
        baseColor 1 1 0
        metalness 0
      }
      geometry Sphere {
        radius 0.03
      }
    }
  ]
  name "solid(2)"
  boundingObject USE shar3
  physics Physics {
  }
  recognitionColors [
    1 1 0
  ]
}
Solid {
  translation 0.59 0.1 0.57
  children [
    DEF shar4 Shape {
      appearance PBRAppearance {
        baseColor 1 1 0
        metalness 0
      }
      geometry Sphere {
        radius 0.03
      }
    }
  ]
  name "solid(3)"
  boundingObject USE shar4
  physics Physics {
  }
  recognitionColors [
    1 1 0
  ]
}
RectangleArena {
  translation -0.0223413 0 0.00495961
  floorSize 2 2
  floorAppearance Parquetry {
    type "dark strip"
    colorOverride 0.0313725 0.0313725 0.427451
    IBLStrength 3
  }
}
DEF все Robot {
  translation -0.039628155917509164 0.06877731322720088 -0.022638121140241628
  rotation -0.10121699265150676 -0.013477685019594404 0.9947730758344324 0.070540818082715
  scale 0.978442 0.978442 0.978442
  children [
    DEF _ Camera {
      translation 0.14 0.25 0
      rotation 0.12942907026382555 -0.9831055337035614 -0.12942807026328268 -1.5878253071795863
      children [
        Solid {
          translation -7.34638e-08 -1.3e-06 0
          rotation 0 0 1 -3.1415853071795863
          children [
            DEF камера Shape {
              appearance PBRAppearance {
              }
              geometry Capsule {
                height 0.001
                radius 0.002
              }
            }
          ]
          boundingObject USE камера
          physics Physics {
          }
        }
      ]
      name "CAM"
      boundingObject USE камера
      physics Physics {
      }
      focus Focus {
      }
      recognition Recognition {
      }
    }
    Solid {
      translation 0.14 0.15 0
      children [
        DEF палка Shape {
          appearance PBRAppearance {
          }
          geometry Cylinder {
            height 0.3
            radius 0.002
          }
        }
      ]
      name "solid(6)"
      boundingObject USE палка
      physics Physics {
      }
    }
    SliderJoint {
      jointParameters JointParameters {
        axis 1 0 1
      }
      device [
        LinearMotor {
          maxPosition 0.002
        }
      ]
      endPoint Solid {
        translation -0.201895 0 0.0417685
        rotation 0 1 0 -2.3561953071795863
        children [
          DEF ездилка1 Shape {
            appearance PBRAppearance {
            }
            geometry Box {
              size 0.001 0.015 0.1
            }
          }
        ]
        name "solid(15)"
        boundingObject USE ездилка1
        physics Physics {
        }
      }
    }
    SliderJoint {
      device [
        LinearMotor {
          minPosition -3
        }
      ]
      endPoint Solid {
        translation -0.2 0 -0.0424264
        rotation 0 1 0 -0.785395307179586
        children [
          DEF ездилка2 Shape {
            appearance PBRAppearance {
            }
            geometry Box {
              size 0.001 0.015 0.1
            }
          }
        ]
        name "solid(16)"
        boundingObject USE ездилка2
        physics Physics {
        }
      }
    }
    SliderJoint {
      device [
        LinearMotor {
        }
      ]
      endPoint Solid {
        translation -0.2 -0.03 -0.0424264
        rotation 0 1 0 -0.785395307179586
        children [
          DEF ездилка3 Shape {
            appearance PBRAppearance {
            }
            geometry Box {
              size 0.001 0.015 0.1
            }
          }
        ]
        name "solid(17)"
        boundingObject USE ездилка3
        physics Physics {
        }
      }
    }
    SliderJoint {
      device [
        LinearMotor {
        }
      ]
      endPoint Solid {
        translation -0.197929 -0.03 0.0404779
        rotation 0 1 0 -2.3561953071795863
        children [
          DEF ездилка4 Shape {
            appearance PBRAppearance {
            }
            geometry Box {
              size 0.001 0.015 0.1
            }
          }
        ]
        name "solid(18)"
        boundingObject USE ездилка4
        physics Physics {
        }
      }
    }
    Solid {
      translation 0.18 0.26 4.98121e-08
      rotation 0.5773489358556708 0.5773509358554485 0.5773509358554485 2.0944
      children [
        Shape {
          appearance PBRAppearance {
          }
          geometry Box {
            size 0.05 0.0005 0.08
          }
        }
      ]
      name "solid(7)"
    }
    Solid {
      translation 0.08 0.03 0
      children [
        DEF хз_что_это Shape {
          appearance PBRAppearance {
          }
          geometry DEF хз_что_это Box {
            size 0.14 0.1 0.1
          }
        }
      ]
      name "solid(5)"
      boundingObject USE хз_что_это
      physics Physics {
      }
    }
    Solid {
      translation -0.13768 0 -0.0333014
      rotation 0 1 0 -2.094395307179586
      children [
        DEF палка_держалка Shape {
          appearance PBRAppearance {
          }
          geometry Box {
            size 0.003 0.02 0.1
          }
        }
      ]
      name "solid(11)"
      boundingObject USE палка_держалка
      physics Physics {
      }
    }
    Solid {
      translation -0.18 -0.01 -0.06
      rotation 1 0 0 -1.5707953071795862
      children [
        DEF палка_сувалка Shape {
          appearance PBRAppearance {
          }
          geometry Box {
            size 0.002 0.002 0.07
          }
        }
      ]
      name "solid(13)"
      boundingObject USE палка_сувалка
      physics Physics {
      }
    }
    Solid {
      translation -0.18 -0.01 0.06
      rotation 1 0 0 -1.5707953071795862
      children [
        DEF палка_сувалка Shape {
          appearance PBRAppearance {
          }
          geometry Box {
            size 0.002 0.002 0.07
          }
        }
      ]
      name "solid(14)"
      boundingObject USE палка_сувалка
      physics Physics {
      }
    }
    Solid {
      translation -0.13768 0 0.0374095
      rotation 0 1 0 -1.047195307179586
      children [
        DEF палка_держалка Shape {
          appearance PBRAppearance {
          }
          geometry Box {
            size 0.003 0.02 0.1
          }
        }
      ]
      name "solid(12)"
      boundingObject USE палка_держалка
      physics Physics {
      }
    }
    Solid {
      translation -0.13 0.04 -0.02
      rotation 0 1 0 1.5708
      children [
        DEF палка_с_сенсором1 Shape {
          appearance PBRAppearance {
          }
          geometry Box {
            size 0.01 0.01 0.14
          }
        }
      ]
      name "solid(9)"
      boundingObject USE палка_с_сенсором1
      physics Physics {
      }
    }
    Solid {
      translation -0.13 0.04 0.025
      rotation 0 1 0 1.5708
      children [
        DEF палка_с_сенсором Shape {
          appearance PBRAppearance {
          }
          geometry Box {
            size 0.01 0.01 0.14
          }
        }
      ]
      name "solid(10)"
      boundingObject USE палка_с_сенсором
      physics Physics {
      }
    }
    Solid {
      translation -0.14 -0.0499999 0
      rotation 0 0 -1 1.5
      children [
        DEF поддон Shape {
          appearance PBRAppearance {
          }
          geometry Box {
            size 0.001 0.1 0.09
          }
        }
      ]
      name "solid(8)"
      boundingObject USE поддон
      physics Physics {
      }
    }
    DEF ds_center DistanceSensor {
      translation -0.145 0 0
      rotation 0 0 1 3.14159
      children [
        DEF controller1 Shape {
          appearance PBRAppearance {
          }
          geometry Box {
            size 0.01 0.01 0.01
          }
        }
      ]
      name "ds_center"
      boundingObject USE controller1
      physics Physics {
      }
    }
    DEF ds_left DistanceSensor {
      translation -0.203 0.0400001 0.0270711
      rotation 0.2588198926057052 -9.156626200564789e-07 0.965925599200442 3.14159
      children [
        DEF controller2 Shape {
          appearance PBRAppearance {
          }
          geometry Box {
            size 0.01 0.01 0.01
          }
        }
      ]
      name "ds_left"
      boundingObject USE controller2
      physics Physics {
      }
      aperture 4
    }
    DEF ds_right DistanceSensor {
      translation -0.203 0.04 -0.021
      rotation -0.2588189595932689 1.5392097596990768e-06 0.9659258491999729 3.14159
      children [
        DEF controller3 Shape {
          appearance PBRAppearance {
          }
          geometry Box {
            size 0.01 0.01 0.01
          }
        }
      ]
      name "ds_right"
      boundingObject USE controller3
      physics Physics {
      }
      rotationStep 0
      aperture 1
      resolution 5
    }
    DEF лидар Lidar {
      translation 0.005 0.06 -3.67318e-08
      rotation 0 1 0 1.5708
      children [
        Shape {
          appearance PBRAppearance {
          }
          geometry Box {
            size 0.01 0.01 0.01
          }
        }
      ]
    }
    DEF wheel1 HingeJoint {
      jointParameters HingeJointParameters {
        position 1.1178996164240997e-06
        axis 0 0 1
        anchor 0.103741 -0.0184537 0.0588052
      }
      device [
        DEF wheel RotationalMotor {
          name "wheel1"
        }
      ]
      endPoint Solid {
        translation 0.10374191963405219 -0.01843888689487856 0.058805310364240485
        rotation 0.9999999999965041 2.0114555501622246e-06 1.7163907402334472e-06 1.5700024949882299
        children [
          DEF wheel1 Shape {
            appearance PBRAppearance {
              baseColor 0.5 0 0
            }
            geometry Cylinder {
              height 0.01
              radius 0.06
            }
          }
        ]
        name "wheel1"
        boundingObject USE wheel1
        physics Physics {
        }
      }
    }
    DEF wheel2 HingeJoint {
      jointParameters HingeJointParameters {
        position -1.2644920364124346e-06
        axis 0 0 1
        anchor 0.103493 -0.0177031 -0.0566547
      }
      device [
        RotationalMotor {
          name "wheel2"
        }
      ]
      endPoint Solid {
        translation 0.10349315811445399 -0.017685063148567836 -0.05665458239907002
        rotation 0.9999999999985447 -1.7053917920514415e-06 -4.673081989888542e-08 1.570000194209746
        children [
          DEF wheel2 Shape {
            appearance PBRAppearance {
              baseColor 0.5 0 0
            }
            geometry Cylinder {
              height 0.01
              radius 0.06
            }
          }
        ]
        name "wheel2"
        boundingObject USE wheel2
        physics Physics {
        }
      }
    }
    DEF wheel3 HingeJoint {
      jointParameters HingeJointParameters {
        position 3.797711075711037e-06
        axis 0 0 1
        anchor -0.07866 -0.0248281 0.0534605
      }
      device [
        RotationalMotor {
          name "wheel3"
        }
      ]
      endPoint Solid {
        translation -0.07866 -0.0247717 0.0534621
        rotation 0.9999999996777355 -1.4336163291181305e-05 2.095241834661052e-05 1.5699944138986566
        children [
          DEF wheel3 Shape {
            appearance PBRAppearance {
              baseColor 0.5 0 0
            }
            geometry Cylinder {
              height 0.01
              radius 0.04
            }
          }
        ]
        name "wheel3"
        boundingObject USE wheel3
        physics Physics {
        }
      }
    }
    DEF wheel4 HingeJoint {
      jointParameters HingeJointParameters {
        position 3.0920481139982475e-06
        axis 0 0 1
        anchor 0.06 0 0.05
      }
      device [
        RotationalMotor {
          name "wheel4"
        }
      ]
      endPoint Solid {
        translation -0.07865992559290852 -0.02477212965543071 -0.05346210000000036
        rotation 0.9999999999982601 1.7126386183321759e-06 7.392569663582816e-07 1.5699991946497065
        children [
          DEF wheel4 Shape {
            appearance PBRAppearance {
              baseColor 0.5 0 0
            }
            geometry Cylinder {
              height 0.01
              radius 0.04
            }
          }
        ]
        name "wheel4"
        boundingObject USE wheel4
        physics Physics {
        }
      }
    }
    DEF кусок_тела_2 Shape {
      appearance PBRAppearance {
      }
      geometry Box {
        size 0.25 0.09 0.06
      }
    }
    Solid {
      translation -0.12 0 0
      children [
        Shape {
          appearance PBRAppearance {
          }
          geometry Cylinder {
            height 0.06
            radius 0.03
          }
        }
      ]
      name "solid(4)"
    }
    DEF цилиндр Shape {
      appearance PBRAppearance {
      }
      geometry Cylinder {
        height 0.1
        radius 0.05
      }
    }
    DEF кусок_тела Shape {
      appearance PBRAppearance {
      }
      geometry Box {
        size 0.22 0.05 0.1
      }
    }
    DEF тело Shape {
      appearance PBRAppearance {
      }
      geometry Box {
        size 0.07 0.1 0.1
      }
    }
  ]
  boundingObject USE кусок_тела
  physics Physics {
  }
  translationStep 0.16
  rotationStep 0.2618
  controller "my_controller2"
  synchronization FALSE
}
